Workbook

Sheet resultado-db-usuario-1
A1: id | B1: requisição | C1: metodo | D1: caminho | E1: rota | F1: statusCode | G1: duracaoMs | H1: iniciadoEm | I1: finalizadoEm | J1: ip | K1: userAgent | L1: createdAt
A2: cmpjwmned008nw2rw28xkyim4 | B2: =resultado_db_usuario_1[[#This Row],[metodo]]&" "&SUBSTITUTE(resultado_db_usuario_1[[#This Row],[rota]],"/api/v1","") -> DELETE /pecas/:id | C2: DELETE | D2: /api/v1/pecas/21 | E2: /api/v1/pecas/:id | F2: 204 | G2: 5.43 | H2: 46166.625 | I2: 46166.625 | J2: ::ffff:127.0.0.1 | K2: Apache-HttpClient/4.5.14 (Java/21.0.11) | L2: 46166.625
A3: cmpjwmngz008xw2rwymi3m97o | B3: =resultado_db_usuario_1[[#This Row],[metodo]]&" "&SUBSTITUTE(resultado_db_usuario_1[[#This Row],[rota]],"/api/v1","") -> DELETE /pecas/:id | C3: DELETE | D3: /api/v1/pecas/21 | E3: /api/v1/pecas/:id | F3: 204 | G3: 6.52 | H3: 46166.625 | I3: 46166.625 | J3: ::ffff:127.0.0.1 | K3: Apache-HttpClient/4.5.14 (Java/21.0.11) | L3: 46166.625
A4: cmpjwmnj70097w2rwbmc3nzlk | B4: =resultado_db_usuario_1[[#This Row],[metodo]]&" "&SUBSTITUTE(resultado_db_usuario_1[[#This Row],[rota]],"/api/v1","") -> DELETE /pecas/:id | C4: DELETE | D4: /api/v1/pecas/21 | E4: /api/v1/pecas/:id | F4: 204 | G4: 5.6 | H4: 46166.625 | I4: 46166.625 | J4: ::ffff:127.0.0.1 | K4: Apache-HttpClient/4.5.14 (Java/21.0.11) | L4: 46166.625
A5: cmpjwmnln009hw2rwk3ib1clc | B5: =resultado_db_usuario_1[[#This Row],[metodo]]&" "&SUBSTITUTE(resultado_db_usuario_1[[#This Row],[rota]],"/api/v1","") -> DELETE /pecas/:id | C5: DELETE | D5: /api/v1/pecas/21 | E5: /api/v1/pecas/:id | F5: 204 | G5: 7.46 | H5: 46166.625 | I5: 46166.625 | J5: ::ffff:127.0.0.1 | K5: Apache-HttpClient/4.5.14 (Java/21.0.11) | L5: 46166.625
A6: cmpjwmnny009rw2rwd21e4m3m | B6: =resultado_db_usuario_1[[#This Row],[metodo]]&" "&SUBSTITUTE(resultado_db_usuario_1[[#This Row],[rota]],"/api/v1","") -> DELETE /pecas/:id | C6: DELETE | D6: /api/v1/pecas/21 | E6: /api/v1/pecas/:id | F6: 204 | G6: 6.3 | H6: 46166.625 | I6: 46166.625 | J6: ::ffff:127.0.0.1 | K6: Apache-HttpClient/4.5.14 (Java/21.0.11) | L6: 46166.625
A7: cmpjwmnqc00a1w2rwr3290ijr | B7: =resultado_db_usuario_1[[#This Row],[metodo]]&" "&SUBSTITUTE(resultado_db_usuario_1[[#This Row],[rota]],"/api/v1","") -> DELETE /pecas/:id | C7: DELETE | D7: /api/v1/pecas/21 | E7: /api/v1/pecas/:id | F7: 204 | G7: 6.1 | H7: 46166.625 | I7: 46166.625 | J7: ::ffff:127.0.0.1 | K7: Apache-HttpClient/4.5.14 (Java/21.0.11) | L7: 46166.625
A8: cmpjwmnsw00abw2rwwlpplyvw | B8: =resultado_db_usuario_1[[#This Row],[metodo]]&" "&SUBSTITUTE(resultado_db_usuario_1[[#This Row],[rota]],"/api/v1","") -> DELETE /pecas/:id | C8: DELETE | D8: /api/v1/pecas/21 | E8: /api/v1/pecas/:id | F8: 204 | G8: 6.66 | H8: 46166.625 | I8: 46166.625 | J8: ::ffff:127.0.0.1 | K8: Apache-HttpClient/4.5.14 (Java/21.0.11) | L8: 46166.625
A9: cmpjwmnvp00alw2rwcw8p71jn | B9: =resultado_db_usuario_1[[#This Row],[metodo]]&" "&SUBSTITUTE(resultado_db_usuario_1[[#This Row],[rota]],"/api/v1","") -> DELETE /pecas/:id | C9: DELETE | D9: /api/v1/pecas/21 | E9: /api/v1/pecas/:id | F9: 204 | G9: 6.38 | H9: 46166.625 | I9: 46166.625 | J9: ::ffff:127.0.0.1 | K9: Apache-HttpClient/4.5.14 (Java/21.0.11) | L9: 46166.625
A10: cmpjwmnxx00avw2rwpk3qrs20 | B10: =resultado_db_usuario_1[[#This Row],[metodo]]&" "&SUBSTITUTE(resultado_db_usuario_1[[#This Row],[rota]],"/api/v1","") -> DELETE /pecas/:id | C10: DELETE | D10: /api/v1/pecas/21 | E10: /api/v1/pecas/:id | F10: 204 | G10: 6.2 | H10: 46166.625 | I10: 46166.625 | J10: ::ffff:127.0.0.1 | K10: Apache-HttpClient/4.5.14 (Java/21.0.11) | L10: 46166.625
A11: cmpjwmo0c00b5w2rw5zcwjlyk | B11: =resultado_db_usuario_1[[#This Row],[metodo]]&" "&SUBSTITUTE(resultado_db_usuario_1[[#This Row],[rota]],"/api/v1","") -> DELETE /pecas/:id | C11: DELETE | D11: /api/v1/pecas/21 | E11: /api/v1/pecas/:id | F11: 204 | G11: 6.18 | H11: 46166.625 | I11: 46166.625 | J11: ::ffff:127.0.0.1 | K11: Apache-HttpClient/4.5.14 (Java/21.0.11) | L11: 46166.625
A12: cmpjwmnc6008ew2rwaioxjmpe | B12: =resultado_db_usuario_1[[#This Row],[metodo]]&" "&SUBSTITUTE(resultado_db_usuario_1[[#This Row],[rota]],"/api/v1","") -> GET /aeronaves/ | C12: GET | D12: /api/v1/aeronaves | E12: /api/v1/aeronaves/ | F12: 200 | G12: 15.28 | H12: 46166.625 | I12: 46166.625 | J12: ::ffff:127.0.0.1 | K12: Apache-HttpClient/4.5.14 (Java/21.0.11) | L12: 46166.625
A13: cmpjwmnew008ow2rw5tlyl3m7 | B13: =resultado_db_usuario_1[[#This Row],[metodo]]&" "&SUBSTITUTE(resultado_db_usuario_1[[#This Row],[rota]],"/api/v1","") -> GET /aeronaves/ | C13: GET | D13: /api/v1/aeronaves | E13: /api/v1/aeronaves/ | F13: 200 | G13: 17.41 | H13: 46166.625 | I13: 46166.625 | J13: ::ffff:127.0.0.1 | K13: Apache-HttpClient/4.5.14 (Java/21.0.11) | L13: 46166.625
... A50: cmpjwmnwk00apw2rwq2ckkns0 | B50: =resultado_db_usuario_1[[#This Row],[metodo]]&" "&SUBSTITUTE(resultado_db_usuario_1[[#This Row],[rota]],"/api/v1","") -> GET /pecas/ | C50: GET | D50: /api/v1/pecas | E50: /api/v1/pecas/ | F50: 200 | G50: 3.64 | H50: 46166.625 | I50: 46166.625 | J50: ::ffff:127.0.0.1 | K50: Apache-HttpClient/4.5.14 (Java/21.0.11) | L50: 46166.625
A51: cmpjwmnz000azw2rw39mkba8z | B51: =resultado_db_usuario_1[[#This Row],[metodo]]&" "&SUBSTITUTE(resultado_db_usuario_1[[#This Row],[rota]],"/api/v1","") -> GET /pecas/ | C51: GET | D51: /api/v1/pecas | E51: /api/v1/pecas/ | F51: 200 | G51: 5 | H51: 46166.625 | I51: 46166.625 | J51: ::ffff:127.0.0.1 | K51: Apache-HttpClient/4.5.14 (Java/21.0.11) | L51: 46166.625
A52: cmpjwmne6008mw2rwmjnss1gl | B52: =resultado_db_usuario_1[[#This Row],[metodo]]&" "&SUBSTITUTE(resultado_db_usuario_1[[#This Row],[rota]],"/api/v1","") -> GET /pecas/:id | C52: GET | D52: /api/v1/pecas/21 | E52: /api/v1/pecas/:id | F52: 200 | G52: 2.73 | H52: 46166.625 | I52: 46166.625 | J52: ::ffff:127.0.0.1 | K52: Apache-HttpClient/4.5.14 (Java/21.0.11) | L52: 46166.625
A53: cmpjwmngr008ww2rweyhbziuj | B53: =resultado_db_usuario_1[[#This Row],[metodo]]&" "&SUBSTITUTE(resultado_db_usuario_1[[#This Row],[rota]],"/api/v1","") -> GET /pecas/:id | C53: GET | D53: /api/v1/pecas/21 | E53: /api/v1/pecas/:id | F53: 200 | G53: 2.97 | H53: 46166.625 | I53: 46166.625 | J53: ::ffff:127.0.0.1 | K53: Apache-HttpClient/4.5.14 (Java/21.0.11) | L53: 46166.625
A54: cmpjwmnj00096w2rw881e0koo | B54: =resultado_db_usuario_1[[#This Row],[metodo]]&" "&SUBSTITUTE(resultado_db_usuario_1[[#This Row],[rota]],"/api/v1","") -> GET /pecas/:id | C54: GET | D54: /api/v1/pecas/21 | E54: /api/v1/pecas/:id | F54: 200 | G54: 2.71 | H54: 46166.625 | I54: 46166.625 | J54: ::ffff:127.0.0.1 | K54: Apache-HttpClient/4.5.14 (Java/21.0.11) | L54: 46166.625
A55: cmpjwmnld009gw2rw0zsm9spj | B55: =resultado_db_usuario_1[[#This Row],[metodo]]&" "&SUBSTITUTE(resultado_db_usuario_1[[#This Row],[rota]],"/api/v1","") -> GET /pecas/:id | C55: GET | D55: /api/v1/pecas/21 | E55: /api/v1/pecas/:id | F55: 200 | G55: 2.43 | H55: 46166.625 | I55: 46166.625 | J55: ::ffff:127.0.0.1 | K55: Apache-HttpClient/4.5.14 (Java/21.0.11) | L55: 46166.625
A56: cmpjwmnnq009qw2rwrtwpkbl9 | B56: =resultado_db_usuario_1[[#This Row],[metodo]]&" "&SUBSTITUTE(resultado_db_usuario_1[[#This Row],[rota]],"/api/v1","") -> GET /pecas/:id | C56: GET | D56: /api/v1/pecas/21 | E56: /api/v1/pecas/:id | F56: 200 | G56: 2.51 | H56: 46166.625 | I56: 46166.625 | J56: ::ffff:127.0.0.1 | K56: Apache-HttpClient/4.5.14 (Java/21.0.11) | L56: 46166.625
A57: cmpjwmnq400a0w2rwe98ib570 | B57: =resultado_db_usuario_1[[#This Row],[metodo]]&" "&SUBSTITUTE(resultado_db_usuario_1[[#This Row],[rota]],"/api/v1","") -> GET /pecas/:id | C57: GET | D57: /api/v1/pecas/21 | E57: /api/v1/pecas/:id | F57: 200 | G57: 2.57 | H57: 46166.625 | I57: 46166.625 | J57: ::ffff:127.0.0.1 | K57: Apache-HttpClient/4.5.14 (Java/21.0.11) | L57: 46166.625
A58: cmpjwmnso00aaw2rwnn977fa7 | B58: =resultado_db_usuario_1[[#This Row],[metodo]]&" "&SUBSTITUTE(resultado_db_usuario_1[[#This Row],[rota]],"/api/v1","") -> GET /pecas/:id | C58: GET | D58: /api/v1/pecas/21 | E58: /api/v1/pecas/:id | F58: 200 | G58: 3.55 | H58: 46166.625 | I58: 46166.625 | J58: ::ffff:127.0.0.1 | K58: Apache-HttpClient/4.5.14 (Java/21.0.11) | L58: 46166.625
A59: cmpjwmnvh00akw2rw6t1bs8hl | B59: =resultado_db_usuario_1[[#This Row],[metodo]]&" "&SUBSTITUTE(resultado_db_usuario_1[[#This Row],[rota]],"/api/v1","") -> GET /pecas/:id | C59: GET | D59: /api/v1/pecas/21 | E59: /api/v1/pecas/:id | F59: 200 | G59: 2.14 | H59: 46166.625 | I59: 46166.625 | J59: ::ffff:127.0.0.1 | K59: Apache-HttpClient/4.5.14 (Java/21.0.11) | L59: 46166.625
A60: cmpjwmnxp00auw2rwzy91o3s6 | B60: =resultado_db_usuario_1[[#This Row],[metodo]]&" "&SUBSTITUTE(resultado_db_usuario_1[[#This Row],[rota]],"/api/v1","") -> GET /pecas/:id | C60: GET | D60: /api/v1/pecas/21 | E60: /api/v1/pecas/:id | F60: 200 | G60: 2.85 | H60: 46166.625 | I60: 46166.625 | J60: ::ffff:127.0.0.1 | K60: Apache-HttpClient/4.5.14 (Java/21.0.11) | L60: 46166.625
A61: cmpjwmo0400b4w2rw01kh7ph9 | B61: =resultado_db_usuario_1[[#This Row],[metodo]]&" "&SUBSTITUTE(resultado_db_usuario_1[[#This Row],[rota]],"/api/v1","") -> GET /pecas/:id | C61: GET | D61: /api/v1/pecas/21 | E61: /api/v1/pecas/:id | F61: 200 | G61: 2.57 | H61: 46166.625 | I61: 46166.625 | J61: ::ffff:127.0.0.1 | K61: Apache-HttpClient/4.5.14 (Java/21.0.11) | L61: 46166.625
A62: cmpjwmncx008iw2rwgvwomy0e | B62: =resultado_db_usuario_1[[#This Row],[metodo]]&" "&SUBSTITUTE(resultado_db_usuario_1[[#This Row],[rota]],"/api/v1","") -> GET /relatorios/ | C62: GET | D62: /api/v1/relatorios | E62: /api/v1/relatorios/ | F62: 200 | G62: 5.21 | H62: 46166.625 | I62: 46166.625 | J62: ::ffff:127.0.0.1 | K62: Apache-HttpClient/4.5.14 (Java/21.0.11) | L62: 46166.625
A63: cmpjwmnfm008sw2rwo7fdm62m | B63: =resultado_db_usuario_1[[#This Row],[metodo]]&" "&SUBSTITUTE(resultado_db_usuario_1[[#This Row],[rota]],"/api/v1","") -> GET /relatorios/ | C63: GET | D63: /api/v1/relatorios | E63: /api/v1/relatorios/ | F63: 200 | G63: 4.31 | H63: 46166.625 | I63: 46166.625 | J63: ::ffff:127.0.0.1 | K63: Apache-HttpClient/4.5.14 (Java/21.0.11) | L63: 46166.625
... A101: cmpjwmnzp00b2w2rw014uebp5 | B101: =resultado_db_usuario_1[[#This Row],[metodo]]&" "&SUBSTITUTE(resultado_db_usuario_1[[#This Row],[rota]],"/api/v1","") -> POST /pecas/ | C101: POST | D101: /api/v1/pecas | E101: /api/v1/pecas/ | F101: 201 | G101: 11.11 | H101: 46166.625 | I101: 46166.625 | J101: ::ffff:127.0.0.1 | K101: Apache-HttpClient/4.5.14 (Java/21.0.11) | L101: 46166.625

Sheet resultado-db-usuario-5
A1: id | B1: requisição | C1: metodo | D1: caminho | E1: rota | F1: statusCode | G1: duracaoMs | H1: iniciadoEm | I1: finalizadoEm | J1: ip | K1: userAgent | L1: createdAt
A2: cmpjx8znd00bfw2rw33km2qiu | B2: =resultado_db_usuario_5[[#This Row],[metodo]]&" "&SUBSTITUTE(resultado_db_usuario_5[[#This Row],[rota]],"/api/v1","") -> DELETE /pecas/:id | C2: DELETE | D2: /api/v1/pecas/21 | E2: /api/v1/pecas/:id | F2: 204 | G2: 5.55 | H2: 46166.637 | I2: 46166.637 | J2: ::ffff:127.0.0.1 | K2: Apache-HttpClient/4.5.14 (Java/21.0.11) | L2: 46166.637
A3: cmpjx8zq200bpw2rw5w4i2dk6 | B3: =resultado_db_usuario_5[[#This Row],[metodo]]&" "&SUBSTITUTE(resultado_db_usuario_5[[#This Row],[rota]],"/api/v1","") -> DELETE /pecas/:id | C3: DELETE | D3: /api/v1/pecas/21 | E3: /api/v1/pecas/:id | F3: 204 | G3: 9.5 | H3: 46166.637 | I3: 46166.637 | J3: ::ffff:127.0.0.1 | K3: Apache-HttpClient/4.5.14 (Java/21.0.11) | L3: 46166.637
A4: cmpjx8ztp00c7w2rw9dfn7db4 | B4: =resultado_db_usuario_5[[#This Row],[metodo]]&" "&SUBSTITUTE(resultado_db_usuario_5[[#This Row],[rota]],"/api/v1","") -> DELETE /pecas/:id | C4: DELETE | D4: /api/v1/pecas/ID_NAO_ENCONTRADO | E4: /api/v1/pecas/:id | F4: 404 | G4: 7.61 | H4: 46166.637 | I4: 46166.637 | J4: ::ffff:127.0.0.1 | K4: Apache-HttpClient/4.5.14 (Java/21.0.11) | L4: 46166.637
A5: cmpjx8zuf00caw2rwx9tm8wf9 | B5: =resultado_db_usuario_5[[#This Row],[metodo]]&" "&SUBSTITUTE(resultado_db_usuario_5[[#This Row],[rota]],"/api/v1","") -> DELETE /pecas/:id | C5: DELETE | D5: /api/v1/pecas/21 | E5: /api/v1/pecas/:id | F5: 204 | G5: 14.37 | H5: 46166.637 | I5: 46166.637 | J5: ::ffff:127.0.0.1 | K5: Apache-HttpClient/4.5.14 (Java/21.0.11) | L5: 46166.637
A6: cmpjx8zyq00cyw2rw4m6x9z43 | B6: =resultado_db_usuario_5[[#This Row],[metodo]]&" "&SUBSTITUTE(resultado_db_usuario_5[[#This Row],[rota]],"/api/v1","") -> DELETE /pecas/:id | C6: DELETE | D6: /api/v1/pecas/21 | E6: /api/v1/pecas/:id | F6: 204 | G6: 6.95 | H6: 46166.637 | I6: 46166.637 | J6: ::ffff:127.0.0.1 | K6: Apache-HttpClient/4.5.14 (Java/21.0.11) | L6: 46166.637
A7: cmpjx8zz700d1w2rwm48se7zi | B7: =resultado_db_usuario_5[[#This Row],[metodo]]&" "&SUBSTITUTE(resultado_db_usuario_5[[#This Row],[rota]],"/api/v1","") -> DELETE /pecas/:id | C7: DELETE | D7: /api/v1/pecas/22 | E7: /api/v1/pecas/:id | F7: 204 | G7: 11.74 | H7: 46166.637 | I7: 46166.637 | J7: ::ffff:127.0.0.1 | K7: Apache-HttpClient/4.5.14 (Java/21.0.11) | L7: 46166.637
A8: cmpjx900100d5w2rwqqdxgxhu | B8: =resultado_db_usuario_5[[#This Row],[metodo]]&" "&SUBSTITUTE(resultado_db_usuario_5[[#This Row],[rota]],"/api/v1","") -> DELETE /pecas/:id | C8: DELETE | D8: /api/v1/pecas/23 | E8: /api/v1/pecas/:id | F8: 204 | G8: 14.18 | H8: 46166.637 | I8: 46166.637 | J8: ::ffff:127.0.0.1 | K8: Apache-HttpClient/4.5.14 (Java/21.0.11) | L8: 46166.637
A9: cmpjx904e00dzw2rwb59m10ma | B9: =resultado_db_usuario_5[[#This Row],[metodo]]&" "&SUBSTITUTE(resultado_db_usuario_5[[#This Row],[rota]],"/api/v1","") -> DELETE /pecas/:id | C9: DELETE | D9: /api/v1/pecas/ID_NAO_ENCONTRADO | E9: /api/v1/pecas/:id | F9: 404 | G9: 7.62 | H9: 46166.637 | I9: 46166.637 | J9: ::ffff:127.0.0.1 | K9: Apache-HttpClient/4.5.14 (Java/21.0.11) | L9: 46166.637
A10: cmpjx904z00e2w2rw77dxizg0 | B10: =resultado_db_usuario_5[[#This Row],[metodo]]&" "&SUBSTITUTE(resultado_db_usuario_5[[#This Row],[rota]],"/api/v1","") -> DELETE /pecas/:id | C10: DELETE | D10: /api/v1/pecas/21 | E10: /api/v1/pecas/:id | F10: 204 | G10: 19.55 | H10: 46166.637 | I10: 46166.637 | J10: ::ffff:127.0.0.1 | K10: Apache-HttpClient/4.5.14 (Java/21.0.11) | L10: 46166.637
A11: cmpjx905y00e7w2rw942imdl9 | B11: =resultado_db_usuario_5[[#This Row],[metodo]]&" "&SUBSTITUTE(resultado_db_usuario_5[[#This Row],[rota]],"/api/v1","") -> DELETE /pecas/:id | C11: DELETE | D11: /api/v1/pecas/22 | E11: /api/v1/pecas/:id | F11: 204 | G11: 14.57 | H11: 46166.637 | I11: 46166.637 | J11: ::ffff:127.0.0.1 | K11: Apache-HttpClient/4.5.14 (Java/21.0.11) | L11: 46166.637
A12: cmpjx907d00eew2rw78m9nweb | B12: =resultado_db_usuario_5[[#This Row],[metodo]]&" "&SUBSTITUTE(resultado_db_usuario_5[[#This Row],[rota]],"/api/v1","") -> DELETE /pecas/:id | C12: DELETE | D12: /api/v1/pecas/23 | E12: /api/v1/pecas/:id | F12: 204 | G12: 26.4 | H12: 46166.637 | I12: 46166.637 | J12: ::ffff:127.0.0.1 | K12: Apache-HttpClient/4.5.14 (Java/21.0.11) | L12: 46166.637
A13: cmpjx90ay00f9w2rwebxh2l88 | B13: =resultado_db_usuario_5[[#This Row],[metodo]]&" "&SUBSTITUTE(resultado_db_usuario_5[[#This Row],[rota]],"/api/v1","") -> DELETE /pecas/:id | C13: DELETE | D13: /api/v1/pecas/21 | E13: /api/v1/pecas/:id | F13: 204 | G13: 6.79 | H13: 46166.637 | I13: 46166.637 | J13: ::ffff:127.0.0.1 | K13: Apache-HttpClient/4.5.14 (Java/21.0.11) | L13: 46166.637
... A43: cmpjx91d500n7w2rwufif13p5 | B43: =resultado_db_usuario_5[[#This Row],[metodo]]&" "&SUBSTITUTE(resultado_db_usuario_5[[#This Row],[rota]],"/api/v1","") -> DELETE /pecas/:id | C43: DELETE | D43: /api/v1/pecas/22 | E43: /api/v1/pecas/:id | F43: 204 | G43: 11.79 | H43: 46166.637 | I43: 46166.637 | J43: ::ffff:127.0.0.1 | K43: Apache-HttpClient/4.5.14 (Java/21.0.11) | L43: 46166.637
A44: cmpjx91e100nbw2rw3tipu3ub | B44: =resultado_db_usuario_5[[#This Row],[metodo]]&" "&SUBSTITUTE(resultado_db_usuario_5[[#This Row],[rota]],"/api/v1","") -> DELETE /pecas/:id | C44: DELETE | D44: /api/v1/pecas/23 | E44: /api/v1/pecas/:id | F44: 204 | G44: 12 | H44: 46166.637 | I44: 46166.637 | J44: ::ffff:127.0.0.1 | K44: Apache-HttpClient/4.5.14 (Java/21.0.11) | L44: 46166.637
A45: cmpjx91f900nnw2rwjpxi0r82 | B45: =resultado_db_usuario_5[[#This Row],[metodo]]&" "&SUBSTITUTE(resultado_db_usuario_5[[#This Row],[rota]],"/api/v1","") -> DELETE /pecas/:id | C45: DELETE | D45: /api/v1/pecas/24 | E45: /api/v1/pecas/:id | F45: 204 | G45: 8.84 | H45: 46166.637 | I45: 46166.637 | J45: ::ffff:127.0.0.1 | K45: Apache-HttpClient/4.5.14 (Java/21.0.11) | L45: 46166.637
A46: cmpjx91h300o0w2rws8oyqcp8 | B46: =resultado_db_usuario_5[[#This Row],[metodo]]&" "&SUBSTITUTE(resultado_db_usuario_5[[#This Row],[rota]],"/api/v1","") -> DELETE /pecas/:id | C46: DELETE | D46: /api/v1/pecas/21 | E46: /api/v1/pecas/:id | F46: 204 | G46: 7.38 | H46: 46166.637 | I46: 46166.637 | J46: ::ffff:127.0.0.1 | K46: Apache-HttpClient/4.5.14 (Java/21.0.11) | L46: 46166.637
A47: cmpjx91hm00o3w2rw9j3obx7a | B47: =resultado_db_usuario_5[[#This Row],[metodo]]&" "&SUBSTITUTE(resultado_db_usuario_5[[#This Row],[rota]],"/api/v1","") -> DELETE /pecas/:id | C47: DELETE | D47: /api/v1/pecas/22 | E47: /api/v1/pecas/:id | F47: 204 | G47: 11.04 | H47: 46166.637 | I47: 46166.637 | J47: ::ffff:127.0.0.1 | K47: Apache-HttpClient/4.5.14 (Java/21.0.11) | L47: 46166.637
A48: cmpjx91j100odw2rw1z9zjlyb | B48: =resultado_db_usuario_5[[#This Row],[metodo]]&" "&SUBSTITUTE(resultado_db_usuario_5[[#This Row],[rota]],"/api/v1","") -> DELETE /pecas/:id | C48: DELETE | D48: /api/v1/pecas/21 | E48: /api/v1/pecas/:id | F48: 204 | G48: 5.89 | H48: 46166.637 | I48: 46166.637 | J48: ::ffff:127.0.0.1 | K48: Apache-HttpClient/4.5.14 (Java/21.0.11) | L48: 46166.637
A49: cmpjx91kx00olw2rwpj7fq1o1 | B49: =resultado_db_usuario_5[[#This Row],[metodo]]&" "&SUBSTITUTE(resultado_db_usuario_5[[#This Row],[rota]],"/api/v1","") -> DELETE /pecas/:id | C49: DELETE | D49: /api/v1/pecas/21 | E49: /api/v1/pecas/:id | F49: 204 | G49: 5.22 | H49: 46166.637 | I49: 46166.637 | J49: ::ffff:127.0.0.1 | K49: Apache-HttpClient/4.5.14 (Java/21.0.11) | L49: 46166.637
A50: cmpjx91ma00oxw2rwd2vgjltd | B50: =resultado_db_usuario_5[[#This Row],[metodo]]&" "&SUBSTITUTE(resultado_db_usuario_5[[#This Row],[rota]],"/api/v1","") -> DELETE /pecas/:id | C50: DELETE | D50: /api/v1/pecas/21 | E50: /api/v1/pecas/:id | F50: 204 | G50: 5.15 | H50: 46166.637 | I50: 46166.637 | J50: ::ffff:127.0.0.1 | K50: Apache-HttpClient/4.5.14 (Java/21.0.11) | L50: 46166.637
A51: cmpjx91n200p1w2rw7kybgrfc | B51: =resultado_db_usuario_5[[#This Row],[metodo]]&" "&SUBSTITUTE(resultado_db_usuario_5[[#This Row],[rota]],"/api/v1","") -> DELETE /pecas/:id | C51: DELETE | D51: /api/v1/pecas/21 | E51: /api/v1/pecas/:id | F51: 204 | G51: 5.77 | H51: 46166.637 | I51: 46166.637 | J51: ::ffff:127.0.0.1 | K51: Apache-HttpClient/4.5.14 (Java/21.0.11) | L51: 46166.637
A52: cmpjx8zl300b6w2rwdeqa0p1m | B52: =resultado_db_usuario_5[[#This Row],[metodo]]&" "&SUBSTITUTE(resultado_db_usuario_5[[#This Row],[rota]],"/api/v1","") -> GET /aeronaves/ | C52: GET | D52: /api/v1/aeronaves | E52: /api/v1/aeronaves/ | F52: 200 | G52: 31.42 | H52: 46166.637 | I52: 46166.637 | J52: ::ffff:127.0.0.1 | K52: Apache-HttpClient/4.5.14 (Java/21.0.11) | L52: 46166.637
A53: cmpjx8znx00bgw2rwfce9pjee | B53: =resultado_db_usuario_5[[#This Row],[metodo]]&" "&SUBSTITUTE(resultado_db_usuario_5[[#This Row],[rota]],"/api/v1","") -> GET /aeronaves/ | C53: GET | D53: /api/v1/aeronaves | E53: /api/v1/aeronaves/ | F53: 200 | G53: 18.51 | H53: 46166.637 | I53: 46166.637 | J53: ::ffff:127.0.0.1 | K53: Apache-HttpClient/4.5.14 (Java/21.0.11) | L53: 46166.637
A54: cmpjx8zqh00bqw2rwm922689q | B54: =resultado_db_usuario_5[[#This Row],[metodo]]&" "&SUBSTITUTE(resultado_db_usuario_5[[#This Row],[rota]],"/api/v1","") -> GET /aeronaves/ | C54: GET | D54: /api/v1/aeronaves | E54: /api/v1/aeronaves/ | F54: 200 | G54: 23.02 | H54: 46166.637 | I54: 46166.637 | J54: ::ffff:127.0.0.1 | K54: Apache-HttpClient/4.5.14 (Java/21.0.11) | L54: 46166.637
A55: cmpjx8zr200brw2rwfxuh83bo | B55: =resultado_db_usuario_5[[#This Row],[metodo]]&" "&SUBSTITUTE(resultado_db_usuario_5[[#This Row],[rota]],"/api/v1","") -> GET /aeronaves/ | C55: GET | D55: /api/v1/aeronaves | E55: /api/v1/aeronaves/ | F55: 200 | G55: 26.63 | H55: 46166.637 | I55: 46166.637 | J55: ::ffff:127.0.0.1 | K55: Apache-HttpClient/4.5.14 (Java/21.0.11) | L55: 46166.637
A56: cmpjx8zud00c9w2rwlj37nqrh | B56: =resultado_db_usuario_5[[#This Row],[metodo]]&" "&SUBSTITUTE(resultado_db_usuario_5[[#This Row],[rota]],"/api/v1","") -> GET /aeronaves/ | C56: GET | D56: /api/v1/aeronaves | E56: /api/v1/aeronaves/ | F56: 200 | G56: 21.33 | H56: 46166.637 | I56: 46166.637 | J56: ::ffff:127.0.0.1 | K56: Apache-HttpClient/4.5.14 (Java/21.0.11) | L56: 46166.637
... A61: cmpjx901400d9w2rwpz09e0mg | B61: =resultado_db_usuario_5[[#This Row],[metodo]]&" "&SUBSTITUTE(resultado_db_usuario_5[[#This Row],[rota]],"/api/v1","") -> GET /aeronaves/ | C61: GET | D61: /api/v1/aeronaves | E61: /api/v1/aeronaves/ | F61: 200 | G61: 33.69 | H61: 46166.637 | I61: 46166.637 | J61: ::ffff:127.0.0.1 | K61: Apache-HttpClient/4.5.14 (Java/21.0.11) | L61: 46166.637
A62: cmpjx902000dew2rwwxz82284 | B62: =resultado_db_usuario_5[[#This Row],[metodo]]&" "&SUBSTITUTE(resultado_db_usuario_5[[#This Row],[rota]],"/api/v1","") -> GET /aeronaves/ | C62: GET | D62: /api/v1/aeronaves | E62: /api/v1/aeronaves/ | F62: 200 | G62: 23 | H62: 46166.637 | I62: 46166.637 | J62: ::ffff:127.0.0.1 | K62: Apache-HttpClient/4.5.14 (Java/21.0.11) | L62: 46166.637
A63: cmpjx905a00e3w2rwueeok1us | B63: =resultado_db_usuario_5[[#This Row],[metodo]]&" "&SUBSTITUTE(resultado_db_usuario_5[[#This Row],[rota]],"/api/v1","") -> GET /aeronaves/ | C63: GET | D63: /api/v1/aeronaves | E63: /api/v1/aeronaves/ | F63: 200 | G63: 30.15 | H63: 46166.637 | I63: 46166.637 | J63: ::ffff:127.0.0.1 | K63: Apache-HttpClient/4.5.14 (Java/21.0.11) | L63: 46166.637
A64: cmpjx906600e8w2rwncosckf0 | B64: =resultado_db_usuario_5[[#This Row],[metodo]]&" "&SUBSTITUTE(resultado_db_usuario_5[[#This Row],[rota]],"/api/v1","") -> GET /aeronaves/ | C64: GET | D64: /api/v1/aeronaves | E64: /api/v1/aeronaves/ | F64: 200 | G64: 27.2 | H64: 46166.637 | I64: 46166.637 | J64: ::ffff:127.0.0.1 | K64: Apache-HttpClient/4.5.14 (Java/21.0.11) | L64: 46166.637
A65: cmpjx907100ecw2rwx9uy9wso | B65: =resultado_db_usuario_5[[#This Row],[metodo]]&" "&SUBSTITUTE(resultado_db_usuario_5[[#This Row],[rota]],"/api/v1","") -> GET /aeronaves/ | C65: GET | D65: /api/v1/aeronaves | E65: /api/v1/aeronaves/ | F65: 200 | G65: 28.97 | H65: 46166.637 | I65: 46166.637 | J65: ::ffff:127.0.0.1 | K65: Apache-HttpClient/4.5.14 (Java/21.0.11) | L65: 46166.637
A66: cmpjx907o00efw2rwyeha3hft | B66: =resultado_db_usuario_5[[#This Row],[metodo]]&" "&SUBSTITUTE(resultado_db_usuario_5[[#This Row],[rota]],"/api/v1","") -> GET /aeronaves/ | C66: GET | D66: /api/v1/aeronaves | E66: /api/v1/aeronaves/ | F66: 200 | G66: 37.45 | H66: 46166.637 | I66: 46166.637 | J66: ::ffff:127.0.0.1 | K66: Apache-HttpClient/4.5.14 (Java/21.0.11) | L66: 46166.637
A67: cmpjx908l00ekw2rw4rtx3d99 | B67: =resultado_db_usuario_5[[#This Row],[metodo]]&" "&SUBSTITUTE(resultado_db_usuario_5[[#This Row],[rota]],"/api/v1","") -> GET /aeronaves/ | C67: GET | D67: /api/v1/aeronaves | E67: /api/v1/aeronaves/ | F67: 200 | G67: 32.03 | H67: 46166.637 | I67: 46166.637 | J67: ::ffff:127.0.0.1 | K67: Apache-HttpClient/4.5.14 (Java/21.0.11) | L67: 46166.637
A68: cmpjx90bp00fgw2rw967jaw3m | B68: =resultado_db_usuario_5[[#This Row],[metodo]]&" "&SUBSTITUTE(resultado_db_usuario_5[[#This Row],[rota]],"/api/v1","") -> GET /aeronaves/ | C68: GET | D68: /api/v1/aeronaves | E68: /api/v1/aeronaves/ | F68: 200 | G68: 21.21 | H68: 46166.637 | I68: 46166.637 | J68: ::ffff:127.0.0.1 | K68: Apache-HttpClient/4.5.14 (Java/21.0.11) | L68: 46166.637
A69: cmpjx90ch00fmw2rwg6wvn189 | B69: =resultado_db_usuario_5[[#This Row],[metodo]]&" "&SUBSTITUTE(resultado_db_usuario_5[[#This Row],[rota]],"/api/v1","") -> GET /aeronaves/ | C69: GET | D69: /api/v1/aeronaves | E69: /api/v1/aeronaves/ | F69: 200 | G69: 21.84 | H69: 46166.637 | I69: 46166.637 | J69: ::ffff:127.0.0.1 | K69: Apache-HttpClient/4.5.14 (Java/21.0.11) | L69: 46166.637
A70: cmpjx90cw00fpw2rw4nn0fmaq | B70: =resultado_db_usuario_5[[#This Row],[metodo]]&" "&SUBSTITUTE(resultado_db_usuario_5[[#This Row],[rota]],"/api/v1","") -> GET /aeronaves/ | C70: GET | D70: /api/v1/aeronaves | E70: /api/v1/aeronaves/ | F70: 200 | G70: 22.22 | H70: 46166.637 | I70: 46166.637 | J70: ::ffff:127.0.0.1 | K70: Apache-HttpClient/4.5.14 (Java/21.0.11) | L70: 46166.637
A71: cmpjx90dh00frw2rwzpz33wuu | B71: =resultado_db_usuario_5[[#This Row],[metodo]]&" "&SUBSTITUTE(resultado_db_usuario_5[[#This Row],[rota]],"/api/v1","") -> GET /aeronaves/ | C71: GET | D71: /api/v1/aeronaves | E71: /api/v1/aeronaves/ | F71: 200 | G71: 31.46 | H71: 46166.637 | I71: 46166.637 | J71: ::ffff:127.0.0.1 | K71: Apache-HttpClient/4.5.14 (Java/21.0.11) | L71: 46166.637
A72: cmpjx90eg00g0w2rwzq4ivvvf | B72: =resultado_db_usuario_5[[#This Row],[metodo]]&" "&SUBSTITUTE(resultado_db_usuario_5[[#This Row],[rota]],"/api/v1","") -> GET /aeronaves/ | C72: GET | D72: /api/v1/aeronaves | E72: /api/v1/aeronaves/ | F72: 200 | G72: 21.37 | H72: 46166.637 | I72: 46166.637 | J72: ::ffff:127.0.0.1 | K72: Apache-HttpClient/4.5.14 (Java/21.0.11) | L72: 46166.637
A73: cmpjx90ho00guw2rw4ulocxas | B73: =resultado_db_usuario_5[[#This Row],[metodo]]&" "&SUBSTITUTE(resultado_db_usuario_5[[#This Row],[rota]],"/api/v1","") -> GET /aeronaves/ | C73: GET | D73: /api/v1/aeronaves | E73: /api/v1/aeronaves/ | F73: 200 | G73: 21.08 | H73: 46166.637 | I73: 46166.637 | J73: ::ffff:127.0.0.1 | K73: Apache-HttpClient/4.5.14 (Java/21.0.11) | L73: 46166.637
...

Sheet resultado-db-usuario-10
A1: id | B1: requisição | C1: metodo | D1: caminho | E1: rota | F1: statusCode | G1: duracaoMs | H1: iniciadoEm | I1: finalizadoEm | J1: ip | K1: userAgent | L1: createdAt
A2: cmpjxfr3c00pbw2rwja53ycv5 | B2: =resultado_db_usuario_10[[#This Row],[metodo]]&" "&SUBSTITUTE(resultado_db_usuario_10[[#This Row],[rota]],"/api/v1","") -> DELETE /pecas/:id | C2: DELETE | D2: /api/v1/pecas/21 | E2: /api/v1/pecas/:id | F2: 204 | G2: 4 | H2: 46166.641 | I2: 46166.641 | J2: ::ffff:127.0.0.1 | K2: Apache-HttpClient/4.5.14 (Java/21.0.11) | L2: 46166.641
A3: cmpjxfr5x00puw2rwmvqcreq0 | B3: =resultado_db_usuario_10[[#This Row],[metodo]]&" "&SUBSTITUTE(resultado_db_usuario_10[[#This Row],[rota]],"/api/v1","") -> DELETE /pecas/:id | C3: DELETE | D3: /api/v1/pecas/21 | E3: /api/v1/pecas/:id | F3: 204 | G3: 6.06 | H3: 46166.641 | I3: 46166.641 | J3: ::ffff:127.0.0.1 | K3: Apache-HttpClient/4.5.14 (Java/21.0.11) | L3: 46166.641
A4: cmpjxfr6500pvw2rwhvfq6uow | B4: =resultado_db_usuario_10[[#This Row],[metodo]]&" "&SUBSTITUTE(resultado_db_usuario_10[[#This Row],[rota]],"/api/v1","") -> DELETE /pecas/:id | C4: DELETE | D4: /api/v1/pecas/22 | E4: /api/v1/pecas/:id | F4: 204 | G4: 6.64 | H4: 46166.641 | I4: 46166.641 | J4: ::ffff:127.0.0.1 | K4: Apache-HttpClient/4.5.14 (Java/21.0.11) | L4: 46166.641
A5: cmpjxfr8g00qjw2rwmcyvwf1s | B5: =resultado_db_usuario_10[[#This Row],[metodo]]&" "&SUBSTITUTE(resultado_db_usuario_10[[#This Row],[rota]],"/api/v1","") -> DELETE /pecas/:id | C5: DELETE | D5: /api/v1/pecas/ID_NAO_ENCONTRADO | E5: /api/v1/pecas/:id | F5: 404 | G5: 5.24 | H5: 46166.641 | I5: 46166.641 | J5: ::ffff:127.0.0.1 | K5: Apache-HttpClient/4.5.14 (Java/21.0.11) | L5: 46166.641
A6: cmpjxfr8s00qmw2rwskn6tssg | B6: =resultado_db_usuario_10[[#This Row],[metodo]]&" "&SUBSTITUTE(resultado_db_usuario_10[[#This Row],[rota]],"/api/v1","") -> DELETE /pecas/:id | C6: DELETE | D6: /api/v1/pecas/21 | E6: /api/v1/pecas/:id | F6: 204 | G6: 9.25 | H6: 46166.641 | I6: 46166.641 | J6: ::ffff:127.0.0.1 | K6: Apache-HttpClient/4.5.14 (Java/21.0.11) | L6: 46166.641
A7: cmpjxfr9v00qxw2rwv4559lja | B7: =resultado_db_usuario_10[[#This Row],[metodo]]&" "&SUBSTITUTE(resultado_db_usuario_10[[#This Row],[rota]],"/api/v1","") -> DELETE /pecas/:id | C7: DELETE | D7: /api/v1/pecas/22 | E7: /api/v1/pecas/:id | F7: 204 | G7: 6.39 | H7: 46166.641 | I7: 46166.641 | J7: ::ffff:127.0.0.1 | K7: Apache-HttpClient/4.5.14 (Java/21.0.11) | L7: 46166.641
A8: cmpjxfrbm00rjw2rwhrjwut5f | B8: =resultado_db_usuario_10[[#This Row],[metodo]]&" "&SUBSTITUTE(resultado_db_usuario_10[[#This Row],[rota]],"/api/v1","") -> DELETE /pecas/:id | C8: DELETE | D8: /api/v1/pecas/21 | E8: /api/v1/pecas/:id | F8: 204 | G8: 5.46 | H8: 46166.641 | I8: 46166.641 | J8: ::ffff:127.0.0.1 | K8: Apache-HttpClient/4.5.14 (Java/21.0.11) | L8: 46166.641
A9: cmpjxfrc200rnw2rwu9tc6b53 | B9: =resultado_db_usuario_10[[#This Row],[metodo]]&" "&SUBSTITUTE(resultado_db_usuario_10[[#This Row],[rota]],"/api/v1","") -> DELETE /pecas/:id | C9: DELETE | D9: /api/v1/pecas/22 | E9: /api/v1/pecas/:id | F9: 204 | G9: 11.64 | H9: 46166.641 | I9: 46166.641 | J9: ::ffff:127.0.0.1 | K9: Apache-HttpClient/4.5.14 (Java/21.0.11) | L9: 46166.641
A10: cmpjxfrdc00rzw2rw78acmg0m | B10: =resultado_db_usuario_10[[#This Row],[metodo]]&" "&SUBSTITUTE(resultado_db_usuario_10[[#This Row],[rota]],"/api/v1","") -> DELETE /pecas/:id | C10: DELETE | D10: /api/v1/pecas/ID_NAO_ENCONTRADO | E10: /api/v1/pecas/:id | F10: 404 | G10: 11.14 | H10: 46166.641 | I10: 46166.641 | J10: ::ffff:127.0.0.1 | K10: Apache-HttpClient/4.5.14 (Java/21.0.11) | L10: 46166.641
A11: cmpjxfrdf00s1w2rwy2402dwa | B11: =resultado_db_usuario_10[[#This Row],[metodo]]&" "&SUBSTITUTE(resultado_db_usuario_10[[#This Row],[rota]],"/api/v1","") -> DELETE /pecas/:id | C11: DELETE | D11: /api/v1/pecas/23 | E11: /api/v1/pecas/:id | F11: 204 | G11: 14.15 | H11: 46166.641 | I11: 46166.641 | J11: ::ffff:127.0.0.1 | K11: Apache-HttpClient/4.5.14 (Java/21.0.11) | L11: 46166.641
A12: cmpjxfrg200svw2rwc72luyfc | B12: =resultado_db_usuario_10[[#This Row],[metodo]]&" "&SUBSTITUTE(resultado_db_usuario_10[[#This Row],[rota]],"/api/v1","") -> DELETE /pecas/:id | C12: DELETE | D12: /api/v1/pecas/21 | E12: /api/v1/pecas/:id | F12: 204 | G12: 11.03 | H12: 46166.641 | I12: 46166.641 | J12: ::ffff:127.0.0.1 | K12: Apache-HttpClient/4.5.14 (Java/21.0.11) | L12: 46166.641
A13: cmpjxfrgi00t1w2rwu3vok0u5 | B13: =resultado_db_usuario_10[[#This Row],[metodo]]&" "&SUBSTITUTE(resultado_db_usuario_10[[#This Row],[rota]],"/api/v1","") -> DELETE /pecas/:id | C13: DELETE | D13: /api/v1/pecas/22 | E13: /api/v1/pecas/:id | F13: 204 | G13: 11.39 | H13: 46166.641 | I13: 46166.641 | J13: ::ffff:127.0.0.1 | K13: Apache-HttpClient/4.5.14 (Java/21.0.11) | L13: 46166.641
A14: cmpjxfrhi00tbw2rwr3tc5qxv | B14: =resultado_db_usuario_10[[#This Row],[metodo]]&" "&SUBSTITUTE(resultado_db_usuario_10[[#This Row],[rota]],"/api/v1","") -> DELETE /pecas/:id | C14: DELETE | D14: /api/v1/pecas/23 | E14: /api/v1/pecas/:id | F14: 204 | G14: 11.25 | H14: 46166.641 | I14: 46166.641 | J14: ::ffff:127.0.0.1 | K14: Apache-HttpClient/4.5.14 (Java/21.0.11) | L14: 46166.641
A15: cmpjxfrhq00tew2rwiwrghpd8 | B15: =resultado_db_usuario_10[[#This Row],[metodo]]&" "&SUBSTITUTE(resultado_db_usuario_10[[#This Row],[rota]],"/api/v1","") -> DELETE /pecas/:id | C15: DELETE | D15: /api/v1/pecas/ID_NAO_ENCONTRADO | E15: /api/v1/pecas/:id | F15: 404 | G15: 5.32 | H15: 46166.641 | I15: 46166.641 | J15: ::ffff:127.0.0.1 | K15: Apache-HttpClient/4.5.14 (Java/21.0.11) | L15: 46166.641
A16: cmpjxfrhz00thw2rw5g0vzkw5 | B16: =resultado_db_usuario_10[[#This Row],[metodo]]&" "&SUBSTITUTE(resultado_db_usuario_10[[#This Row],[rota]],"/api/v1","") -> DELETE /pecas/:id | C16: DELETE | D16: /api/v1/pecas/24 | E16: /api/v1/pecas/:id | F16: 204 | G16: 10.57 | H16: 46166.641 | I16: 46166.641 | J16: ::ffff:127.0.0.1 | K16: Apache-HttpClient/4.5.14 (Java/21.0.11) | L16: 46166.641
A17: cmpjxfrlc00ujw2rwadwk83zs | B17: =resultado_db_usuario_10[[#This Row],[metodo]]&" "&SUBSTITUTE(resultado_db_usuario_10[[#This Row],[rota]],"/api/v1","") -> DELETE /pecas/:id | C17: DELETE | D17: /api/v1/pecas/21 | E17: /api/v1/pecas/:id | F17: 204 | G17: 10.04 | H17: 46166.641 | I17: 46166.641 | J17: ::ffff:127.0.0.1 | K17: Apache-HttpClient/4.5.14 (Java/21.0.11) | L17: 46166.641
A18: cmpjxfrm800usw2rwpvikxy6i | B18: =resultado_db_usuario_10[[#This Row],[metodo]]&" "&SUBSTITUTE(resultado_db_usuario_10[[#This Row],[rota]],"/api/v1","") -> DELETE /pecas/:id | C18: DELETE | D18: /api/v1/pecas/22 | E18: /api/v1/pecas/:id | F18: 204 | G18: 12.12 | H18: 46166.641 | I18: 46166.641 | J18: ::ffff:127.0.0.1 | K18: Apache-HttpClient/4.5.14 (Java/21.0.11) | L18: 46166.641
A19: cmpjxfrms00v0w2rwd36hqp4m | B19: =resultado_db_usuario_10[[#This Row],[metodo]]&" "&SUBSTITUTE(resultado_db_usuario_10[[#This Row],[rota]],"/api/v1","") -> DELETE /pecas/:id | C19: DELETE | D19: /api/v1/pecas/23 | E19: /api/v1/pecas/:id | F19: 204 | G19: 11.03 | H19: 46166.641 | I19: 46166.641 | J19: ::ffff:127.0.0.1 | K19: Apache-HttpClient/4.5.14 (Java/21.0.11) | L19: 46166.641
A20: cmpjxfrni00v9w2rw7ef4vps2 | B20: =resultado_db_usuario_10[[#This Row],[metodo]]&" "&SUBSTITUTE(resultado_db_usuario_10[[#This Row],[rota]],"/api/v1","") -> DELETE /pecas/:id | C20: DELETE | D20: /api/v1/pecas/ID_NAO_ENCONTRADO | E20: /api/v1/pecas/:id | F20: 404 | G20: 11.35 | H20: 46166.641 | I20: 46166.641 | J20: ::ffff:127.0.0.1 | K20: Apache-HttpClient/4.5.14 (Java/21.0.11) | L20: 46166.641
A21: cmpjxfrnx00vdw2rw7mkdrh7k | B21: =resultado_db_usuario_10[[#This Row],[metodo]]&" "&SUBSTITUTE(resultado_db_usuario_10[[#This Row],[rota]],"/api/v1","") -> DELETE /pecas/:id | C21: DELETE | D21: /api/v1/pecas/24 | E21: /api/v1/pecas/:id | F21: 204 | G21: 19.22 | H21: 46166.641 | I21: 46166.641 | J21: ::ffff:127.0.0.1 | K21: Apache-HttpClient/4.5.14 (Java/21.0.11) | L21: 46166.641
A22: cmpjxfro500vgw2rw90u7gz0k | B22: =resultado_db_usuario_10[[#This Row],[metodo]]&" "&SUBSTITUTE(resultado_db_usuario_10[[#This Row],[rota]],"/api/v1","") -> DELETE /pecas/:id | C22: DELETE | D22: /api/v1/pecas/ID_NAO_ENCONTRADO | E22: /api/v1/pecas/:id | F22: 404 | G22: 10.86 | H22: 46166.641 | I22: 46166.641 | J22: ::ffff:127.0.0.1 | K22: Apache-HttpClient/4.5.14 (Java/21.0.11) | L22: 46166.641
A23: cmpjxfrow00vmw2rwx0s5dpdh | B23: =resultado_db_usuario_10[[#This Row],[metodo]]&" "&SUBSTITUTE(resultado_db_usuario_10[[#This Row],[rota]],"/api/v1","") -> DELETE /pecas/:id | C23: DELETE | D23: /api/v1/pecas/25 | E23: /api/v1/pecas/:id | F23: 204 | G23: 22.6 | H23: 46166.641 | I23: 46166.641 | J23: ::ffff:127.0.0.1 | K23: Apache-HttpClient/4.5.14 (Java/21.0.11) | L23: 46166.641
A24: cmpjxfrse00wrw2rw330ocl2i | B24: =resultado_db_usuario_10[[#This Row],[metodo]]&" "&SUBSTITUTE(resultado_db_usuario_10[[#This Row],[rota]],"/api/v1","") -> DELETE /pecas/:id | C24: DELETE | D24: /api/v1/pecas/21 | E24: /api/v1/pecas/:id | F24: 204 | G24: 12.49 | H24: 46166.641 | I24: 46166.641 | J24: ::ffff:127.0.0.1 | K24: Apache-HttpClient/4.5.14 (Java/21.0.11) | L24: 46166.641
A25: cmpjxfrt900x1w2rwa2o49pcs | B25: =resultado_db_usuario_10[[#This Row],[metodo]]&" "&SUBSTITUTE(resultado_db_usuario_10[[#This Row],[rota]],"/api/v1","") -> DELETE /pecas/:id | C25: DELETE | D25: /api/v1/pecas/22 | E25: /api/v1/pecas/:id | F25: 204 | G25: 12.45 | H25: 46166.641 | I25: 46166.641 | J25: ::ffff:127.0.0.1 | K25: Apache-HttpClient/4.5.14 (Java/21.0.11) | L25: 46166.641
A26: cmpjxfruc00xew2rw9yhq5fvk | B26: =resultado_db_usuario_10[[#This Row],[metodo]]&" "&SUBSTITUTE(resultado_db_usuario_10[[#This Row],[rota]],"/api/v1","") -> DELETE /pecas/:id | C26: DELETE | D26: /api/v1/pecas/23 | E26: /api/v1/pecas/:id | F26: 204 | G26: 16.72 | H26: 46166.641 | I26: 46166.641 | J26: ::ffff:127.0.0.1 | K26: Apache-HttpClient/4.5.14 (Java/21.0.11) | L26: 46166.641
A27: cmpjxfruy00xow2rwc3lesz2l | B27: =resultado_db_usuario_10[[#This Row],[metodo]]&" "&SUBSTITUTE(resultado_db_usuario_10[[#This Row],[rota]],"/api/v1","") -> DELETE /pecas/:id | C27: DELETE | D27: /api/v1/pecas/24 | E27: /api/v1/pecas/:id | F27: 204 | G27: 13.82 | H27: 46166.641 | I27: 46166.641 | J27: ::ffff:127.0.0.1 | K27: Apache-HttpClient/4.5.14 (Java/21.0.11) | L27: 46166.641
A28: cmpjxfrvk00xvw2rw24zdap9d | B28: =resultado_db_usuario_10[[#This Row],[metodo]]&" "&SUBSTITUTE(resultado_db_usuario_10[[#This Row],[rota]],"/api/v1","") -> DELETE /pecas/:id | C28: DELETE | D28: /api/v1/pecas/ID_NAO_ENCONTRADO | E28: /api/v1/pecas/:id | F28: 404 | G28: 10.74 | H28: 46166.641 | I28: 46166.641 | J28: ::ffff:127.0.0.1 | K28: Apache-HttpClient/4.5.14 (Java/21.0.11) | L28: 46166.641
A29: cmpjxfrvq00xww2rwqwoj7hw4 | B29: =resultado_db_usuario_10[[#This Row],[metodo]]&" "&SUBSTITUTE(resultado_db_usuario_10[[#This Row],[rota]],"/api/v1","") -> DELETE /pecas/:id | C29: DELETE | D29: /api/v1/pecas/ID_NAO_ENCONTRADO | E29: /api/v1/pecas/:id | F29: 404 | G29: 13.02 | H29: 46166.641 | I29: 46166.641 | J29: ::ffff:127.0.0.1 | K29: Apache-HttpClient/4.5.14 (Java/21.0.11) | L29: 46166.641
A30: cmpjxfrvs00xxw2rwn7ljfehr | B30: =resultado_db_usuario_10[[#This Row],[metodo]]&" "&SUBSTITUTE(resultado_db_usuario_10[[#This Row],[rota]],"/api/v1","") -> DELETE /pecas/:id | C30: DELETE | D30: /api/v1/pecas/ID_NAO_ENCONTRADO | E30: /api/v1/pecas/:id | F30: 404 | G30: 14.7 | H30: 46166.641 | I30: 46166.641 | J30: ::ffff:127.0.0.1 | K30: Apache-HttpClient/4.5.14 (Java/21.0.11) | L30: 46166.641
A31: cmpjxfrvu00xyw2rwyc3at5hu | B31: =resultado_db_usuario_10[[#This Row],[metodo]]&" "&SUBSTITUTE(resultado_db_usuario_10[[#This Row],[rota]],"/api/v1","") -> DELETE /pecas/:id | C31: DELETE | D31: /api/v1/pecas/25 | E31: /api/v1/pecas/:id | F31: 204 | G31: 15.18 | H31: 46166.641 | I31: 46166.641 | J31: ::ffff:127.0.0.1 | K31: Apache-HttpClient/4.5.14 (Java/21.0.11) | L31: 46166.641
A32: cmpjxfry100yiw2rw28wpbhhc | B32: =resultado_db_usuario_10[[#This Row],[metodo]]&" "&SUBSTITUTE(resultado_db_usuario_10[[#This Row],[rota]],"/api/v1","") -> DELETE /pecas/:id | C32: DELETE | D32: /api/v1/pecas/26 | E32: /api/v1/pecas/:id | F32: 204 | G32: 11.65 | H32: 46166.641 | I32: 46166.641 | J32: ::ffff:127.0.0.1 | K32: Apache-HttpClient/4.5.14 (Java/21.0.11) | L32: 46166.641
A33: cmpjxfryt00yvw2rwewtyn2rm | B33: =resultado_db_usuario_10[[#This Row],[metodo]]&" "&SUBSTITUTE(resultado_db_usuario_10[[#This Row],[rota]],"/api/v1","") -> DELETE /pecas/:id | C33: DELETE | D33: /api/v1/pecas/27 | E33: /api/v1/pecas/:id | F33: 204 | G33: 12.56 | H33: 46166.641 | I33: 46166.641 | J33: ::ffff:127.0.0.1 | K33: Apache-HttpClient/4.5.14 (Java/21.0.11) | L33: 46166.641
A34: cmpjxfs0p00zlw2rw06wj60wg | B34: =resultado_db_usuario_10[[#This Row],[metodo]]&" "&SUBSTITUTE(resultado_db_usuario_10[[#This Row],[rota]],"/api/v1","") -> DELETE /pecas/:id | C34: DELETE | D34: /api/v1/pecas/28 | E34: /api/v1/pecas/:id | F34: 204 | G34: 13.17 | H34: 46166.641 | I34: 46166.641 | J34: ::ffff:127.0.0.1 | K34: Apache-HttpClient/4.5.14 (Java/21.0.11) | L34: 46166.641
A35: cmpjxfs1h00zuw2rwjs5uqyv1 | B35: =resultado_db_usuario_10[[#This Row],[metodo]]&" "&SUBSTITUTE(resultado_db_usuario_10[[#This Row],[rota]],"/api/v1","") -> DELETE /pecas/:id | C35: DELETE | D35: /api/v1/pecas/29 | E35: /api/v1/pecas/:id | F35: 204 | G35: 15.61 | H35: 46166.641 | I35: 46166.641 | J35: ::ffff:127.0.0.1 | K35: Apache-HttpClient/4.5.14 (Java/21.0.11) | L35: 46166.641
A36: cmpjxfs2q010bw2rw0e76awk4 | B36: =resultado_db_usuario_10[[#This Row],[metodo]]&" "&SUBSTITUTE(resultado_db_usuario_10[[#This Row],[rota]],"/api/v1","") -> DELETE /pecas/:id | C36: DELETE | D36: /api/v1/pecas/30 | E36: /api/v1/pecas/:id | F36: 204 | G36: 12.83 | H36: 46166.641 | I36: 46166.641 | J36: ::ffff:127.0.0.1 | K36: Apache-HttpClient/4.5.14 (Java/21.0.11) | L36: 46166.641
A37: cmpjxfs33010hw2rwt84mu80b | B37: =resultado_db_usuario_10[[#This Row],[metodo]]&" "&SUBSTITUTE(resultado_db_usuario_10[[#This Row],[rota]],"/api/v1","") -> DELETE /pecas/:id | C37: DELETE | D37: /api/v1/pecas/31 | E37: /api/v1/pecas/:id | F37: 204 | G37: 9.22 | H37: 46166.641 | I37: 46166.641 | J37: ::ffff:127.0.0.1 | K37: Apache-HttpClient/4.5.14 (Java/21.0.11) | L37: 46166.641
A38: cmpjxfs3b010lw2rwt0oxezpz | B38: =resultado_db_usuario_10[[#This Row],[metodo]]&" "&SUBSTITUTE(resultado_db_usuario_10[[#This Row],[rota]],"/api/v1","") -> DELETE /pecas/:id | C38: DELETE | D38: /api/v1/pecas/ID_NAO_ENCONTRADO | E38: /api/v1/pecas/:id | F38: 404 | G38: 11.32 | H38: 46166.641 | I38: 46166.641 | J38: ::ffff:127.0.0.1 | K38: Apache-HttpClient/4.5.14 (Java/21.0.11) | L38: 46166.641
A39: cmpjxfs3e010mw2rwpx2ebomn | B39: =resultado_db_usuario_10[[#This Row],[metodo]]&" "&SUBSTITUTE(resultado_db_usuario_10[[#This Row],[rota]],"/api/v1","") -> DELETE /pecas/:id | C39: DELETE | D39: /api/v1/pecas/ID_NAO_ENCONTRADO | E39: /api/v1/pecas/:id | F39: 404 | G39: 11.72 | H39: 46166.641 | I39: 46166.641 | J39: ::ffff:127.0.0.1 | K39: Apache-HttpClient/4.5.14 (Java/21.0.11) | L39: 46166.641
A40: cmpjxfs3h010nw2rw9xnf62jq | B40: =resultado_db_usuario_10[[#This Row],[metodo]]&" "&SUBSTITUTE(resultado_db_usuario_10[[#This Row],[rota]],"/api/v1","") -> DELETE /pecas/:id | C40: DELETE | D40: /api/v1/pecas/ID_NAO_ENCONTRADO | E40: /api/v1/pecas/:id | F40: 404 | G40: 13.71 | H40: 46166.641 | I40: 46166.641 | J40: ::ffff:127.0.0.1 | K40: Apache-HttpClient/4.5.14 (Java/21.0.11) | L40: 46166.641
...

Sheet Resumo-DB
B2: Usuários: 1 | H2: Usuários: 5 | N2: Usuários: 10
B4: Requisição | C4: Quantidade de Amostras (n) | D4: Média de Duração (ms) | E4: Mín. de Duração (ms) | F4: Máx. de Duração (ms) | H4: Requisição | I4: Quantidade de Amostras (n) | J4: Média de Duração (ms) | K4: Mín. de Duração (ms) | L4: Máx. de Duração (ms) | N4: Rótulos de Linha | O4: Contagem de duracaoMs | P4: Média de duracaoMs2 | Q4: Mín. de duracaoMs2 | R4: Máx. de duracaoMs2
B5: DELETE /pecas/:id | C5: 10 | D5: 6.283 | E5: 5.43 | F5: 7.46 | H5: DELETE /pecas/:id | I5: 50 | J5: 11.177347 | K5: 4.73 | L5: 26.4 | N5: DELETE /pecas/:id | O5: 100 | P5: 11.298889 | Q5: 3.03 | R5: 22.6
B6: GET /aeronaves/ | C6: 10 | D6: 16.419 | E6: 13.69 | F6: 24.57 | H6: GET /aeronaves/ | I6: 50 | J6: 29.008776 | K6: 14.3 | L6: 68.8 | N6: GET /aeronaves/ | O6: 100 | P6: 24.023878 | Q6: 8.58 | R6: 49.95
B7: GET /etapas/ | C7: 10 | D7: 6.852 | E7: 5.31 | F7: 10.18 | H7: GET /etapas/ | I7: 50 | J7: 12.0896 | K7: 5.32 | L7: 27.8 | N7: GET /etapas/ | O7: 100 | P7: 10.6932 | Q7: 3.54 | R7: 23.96
B8: GET /funcionarios/ | C8: 10 | D8: 3.653 | E8: 3.07 | F8: 4.4 | H8: GET /funcionarios/ | I8: 50 | J8: 8.3804 | K8: 2.81 | L8: 21.38 | N8: GET /funcionarios/ | O8: 100 | P8: 8.4299 | Q8: 2.21 | R8: 22.66
B9: GET /pecas/ | C9: 10 | D9: 4.36 | E9: 3.35 | F9: 5.56 | H9: GET /pecas/ | I9: 50 | J9: 8.9308 | K9: 3.22 | L9: 23.63 | N9: GET /pecas/ | O9: 100 | P9: 8.9392929 | Q9: 2.58 | R9: 20.04
B10: GET /pecas/:id | C10: 10 | D10: 2.703 | E10: 2.14 | F10: 3.55 | H10: GET /pecas/:id | I10: 50 | J10: 7.0683673 | K10: 2.71 | L10: 17.11 | N10: GET /pecas/:id | O10: 100 | P10: 8.2624658 | Q10: 1.75 | R10: 19.86
B11: GET /relatorios/ | C11: 10 | D11: 4.666 | E11: 3.53 | F11: 5.28 | H11: GET /relatorios/ | I11: 50 | J11: 8.217 | K11: 3.12 | L11: 25.96 | N11: GET /relatorios/ | O11: 100 | P11: 9.979798 | Q11: 2.33 | R11: 32.97
B12: GET /testes/ | C12: 10 | D12: 3.753 | E12: 2.72 | F12: 4.48 | H12: GET /testes/ | I12: 50 | J12: 7.3926 | K12: 3.48 | L12: 35.07 | N12: GET /testes/ | O12: 100 | P12: 9.069596 | Q12: 1.96 | R12: 25.09
B13: PATCH /pecas/:id | C13: 10 | D13: 10.416 | E13: 8.37 | F13: 12.61 | H13: PATCH /pecas/:id | I13: 50 | J13: 15.658776 | K13: 3.15 | L13: 49.08 | N13: PATCH /pecas/:id | O13: 100 | P13: 21.091528 | Q13: 5.46 | R13: 43.58
B14: POST /pecas/ | C14: 10 | D14: 11.621 | E14: 9.18 | F14: 18.97 | H14: POST /pecas/ | I14: 50 | J14: 21.053673 | K14: 8.49 | L14: 37.49 | N14: POST /pecas/ | O14: 100 | P14: 25.583434 | Q14: 7.5 | R14: 47.6
B15: Total Geral | C15: 100 | D15: 7.1 | E15: 2.14 | F15: 24.57 | H15: Total Geral | I15: 500 | J15: 12.858384 | K15: 2.71 | L15: 68.8 | N15: Total Geral | O15: 1000 | P15: 13.727289 | Q15: 1.75 | R15: 49.95

Sheet Resumo-JMeter
B2: Usuários: 1 | Q2: Usuários: 5 | AF2: Usuários: 10
B4: Requests | C4: Executions | F4: Response Times (ms) | M4: Throughput | N4: Network (KB/sec) | Q4: Requests | R4: Executions | U4: Response Times (ms) | AB4: Throughput | AC4: Network (KB/sec) | AF4: Requests | AG4: Executions | AJ4: Response Times (ms) | AQ4: Throughput | AR4: Network (KB/sec)
B5: Label | C5: #Samples | D5: FAIL | E5: Error % | F5: Average | G5: Min | H5: Max | I5: Median | J5: 90th pct | K5: 95th pct | L5: 99th pct | M5: Transactions/s | N5: Received | O5: Sent | Q5: Label | R5: #Samples | S5: FAIL | T5: Error % | U5: Average | V5: Min | W5: Max | X5: Median | Y5: 90th pct | Z5: 95th pct | AA5: 99th pct | AB5: Transactions/s | AC5: Received | AD5: Sent | AF5: Label | AG5: #Samples | AH5: FAIL | AI5: Error % | AJ5: Average | AK5: Min | AL5: Max | AM5: Median | AN5: 90th pct | AO5: 95th pct | AP5: 99th pct | AQ5: Transactions/s | AR5: Received | AS5: Sent
B6: Total | C6: 100 | D6: 0 | E6: 0 | F6: 8.49 | G6: 3 | H6: 26 | I6: 7 | J6: 14.9 | K6: 18 | L6: 25.95 | M6: 112.49 | N6: 412.76 | O6: 22.35 | Q6: Total | R6: 500 | S6: 40 | T6: 0.08 | U6: 19.94 | V6: 3 | W6: 71 | X6: 17 | Y6: 34 | Z6: 42 | AA6: 54.99 | AB6: 185.32 | AC6: 683.8 | AD6: 37.04 | AF6: Total | AG6: 1000 | AH6: 108 | AI6: 0.108 | AJ6: 21.69 | AK6: 2 | AL6: 66 | AM6: 20 | AN6: 37 | AO6: 43 | AP6: 55 | AQ6: 332.23 | AR6: 1232.46 | AS6: 66.53
B7: DELETE /pecas/{id} | C7: 10 | D7: 0 | E7: 0 | F7: 7.9 | G7: 7 | H7: 11 | I7: 7.5 | J7: 10.8 | K7: 11 | L7: 11 | M7: 12.53 | N7: 2.03 | O7: 2.28 | Q7: DELETE /pecas/{id} | R7: 50 | S7: 10 | T7: 0.2 | U7: 18.14 | V7: 7 | W7: 42 | X7: 16.5 | Y7: 28.9 | Z7: 33 | AA7: 42 | AB7: 19.31 | AC7: 3.66 | AD7: 3.56 | AF7: DELETE /pecas/{id} | AG7: 100 | AH7: 27 | AI7: 0.27 | AJ7: 19.11 | AK7: 5 | AL7: 45 | AM7: 20 | AN7: 26.9 | AO7: 28.95 | AP7: 44.9 | AQ7: 33.92 | AR7: 6.77 | AS7: 6.3
B8: GET /aeronaves | C8: 10 | D8: 0 | E8: 0 | F8: 17.9 | G8: 14 | H8: 26 | I8: 17.5 | J8: 25.3 | K8: 26 | L8: 26 | M8: 12.22 | N8: 173.8 | O8: 1.97 | Q8: GET /aeronaves | R8: 50 | S8: 0 | T8: 0 | U8: 36.36 | V8: 17 | W8: 71 | X8: 34.5 | Y8: 52 | Z8: 58.8 | AA8: 71 | AB8: 18.96 | AC8: 274.5 | AD8: 3.06 | AF8: GET /aeronaves | AG8: 100 | AH8: 0 | AI8: 0 | AJ8: 31.86 | AK8: 11 | AL8: 66 | AM8: 31 | AN8: 48 | AO8: 54.95 | AP8: 65.95 | AQ8: 33.81 | AR8: 496.86 | AS8: 5.45
B9: GET /etapas | C9: 10 | D9: 0 | E9: 0 | F9: 8.5 | G9: 7 | H9: 11 | I9: 8 | J9: 10.9 | K9: 11 | L9: 11 | M9: 12.35 | N9: 43.79 | O9: 1.95 | Q9: GET /etapas | R9: 50 | S9: 0 | T9: 0 | U9: 20.5 | V9: 8 | W9: 42 | X9: 20 | Y9: 30.9 | Z9: 41 | AA9: 42 | AB9: 19.16 | AC9: 67.95 | AD9: 3.03 | AF9: GET /etapas | AG9: 100 | AH9: 0 | AI9: 0 | AJ9: 20.11 | AK9: 5 | AL9: 42 | AM9: 20 | AN9: 30.8 | AO9: 34 | AP9: 41.99 | AQ9: 33.97 | AR9: 120.48 | AS9: 5.37
B10: GET /funcionarios | C10: 10 | D10: 0 | E10: 0 | F10: 5.7 | G10: 5 | H10: 9 | I10: 5 | J10: 8.7 | K10: 9 | L10: 9 | M10: 12.41 | N10: 26.18 | O10: 2.04 | Q10: GET /funcionarios | R10: 50 | S10: 0 | T10: 0 | U10: 16.64 | V10: 5 | W10: 42 | X10: 15.5 | Y10: 28 | Z10: 34.8 | AA10: 42 | AB10: 19.16 | AC10: 40.44 | AD10: 3.14 | AF10: GET /funcionarios | AG10: 100 | AH10: 0 | AI10: 0 | AJ10: 17.05 | AK10: 4 | AL10: 40 | AM10: 18 | AN10: 23.9 | AO10: 32.7 | AP10: 39.97 | AQ10: 33.97 | AR10: 71.68 | AS10: 5.57
B11: GET /pecas | C11: 10 | D11: 0 | E11: 0 | F11: 5.6 | G11: 4 | H11: 7 | I11: 6 | J11: 7 | K11: 7 | L11: 7 | M11: 12.39 | N11: 37.1 | O11: 1.95 | Q11: GET /pecas | R11: 50 | S11: 0 | T11: 0 | U11: 15.94 | V11: 4 | W11: 54 | X11: 13 | Y11: 27.8 | Z11: 33 | AA11: 54 | AB11: 19.18 | AC11: 57.43 | AD11: 3.02 | AF11: GET /pecas | AG11: 100 | AH11: 0 | AI11: 0 | AJ11: 16.52 | AK11: 4 | AL11: 38 | AM11: 17.5 | AN11: 25 | AO11: 27.95 | AP11: 38 | AQ11: 33.97 | AR11: 101.7 | AS11: 5.34
B12: GET /pecas/{id} | C12: 10 | D12: 0 | E12: 0 | F12: 3.8 | G12: 3 | H12: 6 | I12: 3.5 | J12: 5.9 | K12: 6 | L12: 6 | M12: 12.59 | N12: 7.2 | O12: 2.02 | Q12: GET /pecas/{id} | R12: 50 | S12: 10 | T12: 0.2 | U12: 12.7 | V12: 3 | W12: 34 | X12: 10.5 | Y12: 24 | Z12: 31.35 | AA12: 34 | AB12: 19.33 | AC12: 10.02 | AD12: 3.15 | AF12: GET /pecas/{id} | AG12: 100 | AH12: 27 | AI12: 0.27 | AJ12: 16.26 | AK12: 2 | AL12: 38 | AM12: 18 | AN12: 23.9 | AO12: 25.95 | AP12: 37.94 | AQ12: 33.94 | AR12: 16.96 | AS12: 5.57
B13: GET /relatorios | C13: 10 | D13: 0 | E13: 0 | F13: 5.6 | G13: 5 | H13: 7 | I13: 5.5 | J13: 6.9 | K13: 7 | L13: 7 | M13: 12.39 | N13: 112.9 | O13: 2.01 | Q13: GET /relatorios | R13: 50 | S13: 0 | T13: 0 | U13: 15.44 | V13: 4 | W13: 50 | X13: 12.5 | Y13: 25.8 | Z13: 37.9 | AA13: 50 | AB13: 19.2 | AC13: 174.95 | AD13: 3.11 | AF13: GET /relatorios | AG13: 100 | AH13: 0 | AI13: 0 | AJ13: 18.04 | AK13: 4 | AL13: 45 | AM13: 18 | AN13: 26 | AO13: 34.85 | AP13: 44.94 | AQ13: 33.97 | AR13: 309.49 | AS13: 5.51
B14: GET /testes | C14: 10 | D14: 0 | E14: 0 | F14: 4.8 | G14: 4 | H14: 6 | I14: 5 | J14: 5.9 | K14: 6 | L14: 6 | M14: 12.39 | N14: 35.23 | O14: 1.96 | Q14: GET /testes | R14: 50 | S14: 0 | T14: 0 | U14: 14.38 | V14: 4 | W14: 52 | X14: 13 | Y14: 25.9 | Z14: 31.8 | AA14: 52 | AB14: 19.23 | AC14: 54.67 | AD14: 3.04 | AF14: GET /testes | AG14: 100 | AH14: 0 | AI14: 0 | AJ14: 17.9 | AK14: 3 | AL14: 39 | AM14: 18 | AN14: 27.9 | AO14: 31.9 | AP14: 38.98 | AQ14: 33.97 | AR14: 96.56 | AS14: 5.37
B15: PATCH /pecas/{id} | C15: 10 | D15: 0 | E15: 0 | F15: 11.8 | G15: 10 | H15: 14 | I15: 12 | J15: 14 | K15: 14 | L15: 14 | M15: 12.42 | N15: 7.1 | O15: 4.34 | Q15: PATCH /pecas/{id} | R15: 50 | S15: 10 | T15: 0.2 | U15: 22 | V15: 6 | W15: 55 | X15: 20.5 | Y15: 37.5 | Z15: 50.05 | AA15: 55 | AB15: 19.26 | AC15: 9.99 | AD15: 6.81 | AF15: PATCH /pecas/{id} | AG15: 100 | AH15: 27 | AI15: 0.27 | AJ15: 25.98 | AK15: 4 | AL15: 59 | AM15: 25.5 | AN15: 41 | AO15: 47.9 | AP15: 58.94 | AQ15: 33.89 | AR15: 16.93 | AS15: 12.02
B16: POST /pecas | C16: 10 | D16: 0 | E16: 0 | F16: 13.3 | G16: 10 | H16: 21 | I16: 13 | J16: 20.3 | K16: 21 | L16: 21 | M16: 12.27 | N16: 6.95 | O16: 4.11 | Q16: POST /pecas | R16: 50 | S16: 10 | T16: 0.2 | U16: 27.26 | V16: 10 | W16: 50 | X16: 27 | Y16: 36.9 | Z16: 44.35 | AA16: 50 | AB16: 19.21 | AC16: 11.3 | AD16: 6.46 | AF16: POST /pecas | AG16: 100 | AH16: 27 | AI16: 0.27 | AJ16: 34.03 | AK16: 9 | AL16: 63 | AM16: 35 | AN16: 50.8 | AO16: 57.85 | AP16: 63 | AQ16: 33.86 | AR16: 20.17 | AS16: 11.41

Sheet Resumo
B2: Usuários: 1 | Z2: Usuários: 5 | AX2: Usuários: 10
B4: Requests | C4: Executions | F4: Response Times (ms) | M4: Latência de Requisição (ms) | P4: Tempo de Processamento (ms) | S4: Latência de Resposta (ms) | V4: Throughput | W4: Network (KB/sec) | Z4: Requests | AA4: Executions | AD4: Response Times (ms) | AK4: Latência de Requisição (ms) | AN4: Tempo de Processamento (ms) | AQ4: Latência de Resposta (ms) | AT4: Throughput | AU4: Network (KB/sec) | AX4: Requests | AY4: Executions | BB4: Response Times (ms) | BI4: Latência de Requisição (ms) | BL4: Tempo de Processamento (ms) | BO4: Latência de Resposta (ms) | BR4: Throughput | BS4: Network (KB/sec)
B5: Label | C5: #Samples | D5: FAIL | E5: Error % | F5: Average | G5: Min | H5: Max | I5: Median | J5: 90th pct | K5: 95th pct | L5: 99th pct | M5: Average | N5: Min | O5: Max | P5: Average | Q5: Min | R5: Max | S5: Average | T5: Min | U5: Max | V5: Transactions/s | W5: Received | X5: Sent | Z5: Label | AA5: #Samples | AB5: FAIL | AC5: Error % | AD5: Average | AE5: Min | AF5: Max | AG5: Median | AH5: 90th pct | AI5: 95th pct | AJ5: 99th pct | AK5: Average | AL5: Min | AM5: Max | AN5: Average | AO5: Min | AP5: Max | AQ5: Average | AR5: Min | AS5: Max | AT5: Transactions/s | AU5: Received | AV5: Sent | AX5: Label | AY5: #Samples | AZ5: FAIL | BA5: Error % | BB5: Average | BC5: Min | BD5: Max | BE5: Median | BF5: 90th pct | BG5: 95th pct | BH5: 99th pct | BI5: Average | BJ5: Min | BK5: Max | BL5: Average | BM5: Min | BN5: Max | BO5: Average | BP5: Min | BQ5: Max | BR5: Transactions/s | BS5: Received | BT5: Sent
B6: Total | C6: 100 | D6: 0 | E6: 0 | F6: 8.49 | G6: 3 | H6: 26 | I6: 7 | J6: 14.9 | K6: 18 | L6: 25.95 | M6: =(F6-P6)/2 -> 0.695 | N6: =(G6-Q6)/2 -> 0.43 | O6: =(H6-R6)/2 -> 0.715 | P6: =GETPIVOTDATA("Média de Duração (ms)",'Resumo-DB'!$B$4) -> 7.1 | Q6: =GETPIVOTDATA("Mín. de Duração (ms)",'Resumo-DB'!$B$4) -> 2.14 | R6: =GETPIVOTDATA("Máx. de Duração (ms)",'Resumo-DB'!$B$4) -> 24.57 | S6: =F6-P6-M6 -> 0.695 | T6: =G6-Q6-N6 -> 0.43 | U6: =H6-R6-O6 -> 0.715 | V6: 112.49 | W6: 412.76 | X6: 22.35 | Z6: Total | AA6: 500 | AB6: 40 | AC6: 0.08 | AD6: 19.94 | AE6: 3 | AF6: 71 | AG6: 17 | AH6: 34 | AI6: 42 | AJ6: 54.99 | AK6: =(AD6-AN6)/2 -> 3.5408081 | AL6: =(AE6-AO6)/2 -> 0.145 | AM6: =(AF6-AP6)/2 -> 1.1 | AN6: =GETPIVOTDATA("Média de Duração (ms)",'Resumo-DB'!$H$4) -> 12.858384 | AO6: =GETPIVOTDATA("Mín. de Duração (ms)",'Resumo-DB'!$H$4) -> 2.71 | AP6: =GETPIVOTDATA("Máx. de Duração (ms)",'Resumo-DB'!$H$4) -> 68.8 | AQ6: =AD6-AN6-AK6 -> 3.5408081 | AR6: =AE6-AO6-AL6 -> 0.145 | AS6: =AF6-AP6-AM6 -> 1.1 | AT6: 185.32 | AU6: 683.8 | AV6: 37.04 | AX6: Total | AY6: 1000 | AZ6: 108 | BA6: 0.108 | BB6: 21.69 | BC6: 2 | BD6: 66 | BE6: 20 | BF6: 37 | BG6: 43 | BH6: 55 | BI6: =(BB6-BL6)/2 -> 3.9813557 | BJ6: =(BC6-BM6)/2 -> 0.125 | BK6: =(BD6-BN6)/2 -> 8.025 | BL6: =GETPIVOTDATA("Média de duracaoMs2",'Resumo-DB'!$N$4) -> 13.727289 | BM6: =GETPIVOTDATA("Mín. de duracaoMs2",'Resumo-DB'!$N$4) -> 1.75 | BN6: =GETPIVOTDATA("Máx. de duracaoMs2",'Resumo-DB'!$N$4) -> 49.95 | BO6: =BB6-BL6-BI6 -> 3.9813557 | BP6: =BC6-BM6-BJ6 -> 0.125 | BQ6: =BD6-BN6-BK6 -> 8.025 | BR6: 332.23 | BS6: 1232.46 | BT6: 66.53
B7: DELETE /pecas/{id} | C7: 10 | D7: 0 | E7: 0 | F7: 7.9 | G7: 7 | H7: 11 | I7: 7.5 | J7: 10.8 | K7: 11 | L7: 11 | M7: =(F7-P7)/2 -> 0.8085 | N7: =(G7-Q7)/2 -> 0.785 | O7: =(H7-R7)/2 -> 1.77 | P7: =GETPIVOTDATA("Média de Duração (ms)",'Resumo-DB'!$B$4,"requisição","DELETE /pecas/:id") -> 6.283 | Q7: =GETPIVOTDATA("Mín. de Duração (ms)",'Resumo-DB'!$B$4,"requisição","DELETE /pecas/:id") -> 5.43 | R7: =GETPIVOTDATA("Máx. de Duração (ms)",'Resumo-DB'!$B$4,"requisição","DELETE /pecas/:id") -> 7.46 | S7: =F7-P7-M7 -> 0.8085 | T7: =G7-Q7-N7 -> 0.785 | U7: =H7-R7-O7 -> 1.77 | V7: 12.53 | W7: 2.03 | X7: 2.28 | Z7: DELETE /pecas/{id} | AA7: 50 | AB7: 10 | AC7: 0.2 | AD7: 18.14 | AE7: 7 | AF7: 42 | AG7: 16.5 | AH7: 28.9 | AI7: 33 | AJ7: 42 | AK7: =(AD7-AN7)/2 -> 3.4813265 | AL7: =(AE7-AO7)/2 -> 1.135 | AM7: =(AF7-AP7)/2 -> 7.8 | AN7: =GETPIVOTDATA("Média de Duração (ms)",'Resumo-DB'!$H$4,"requisição","DELETE /pecas/:id") -> 11.177347 | AO7: =GETPIVOTDATA("Mín. de Duração (ms)",'Resumo-DB'!$H$4,"requisição","DELETE /pecas/:id") -> 4.73 | AP7: =GETPIVOTDATA("Máx. de Duração (ms)",'Resumo-DB'!$H$4,"requisição","DELETE /pecas/:id") -> 26.4 | AQ7: =AD7-AN7-AK7 -> 3.4813265 | AR7: =AE7-AO7-AL7 -> 1.135 | AS7: =AF7-AP7-AM7 -> 7.8 | AT7: 19.31 | AU7: 3.66 | AV7: 3.56 | AX7: DELETE /pecas/{id} | AY7: 100 | AZ7: 27 | BA7: 0.27 | BB7: 19.11 | BC7: 5 | BD7: 45 | BE7: 20 | BF7: 26.9 | BG7: 28.95 | BH7: 44.9 | BI7: =(BB7-BL7)/2 -> 3.9055556 | BJ7: =(BC7-BM7)/2 -> 0.985 | BK7: =(BD7-BN7)/2 -> 11.2 | BL7: =GETPIVOTDATA("Média de duracaoMs2",'Resumo-DB'!$N$4,"requisição","DELETE /pecas/:id") -> 11.298889 | BM7: =GETPIVOTDATA("Mín. de duracaoMs2",'Resumo-DB'!$N$4,"requisição","DELETE /pecas/:id") -> 3.03 | BN7: =GETPIVOTDATA("Máx. de duracaoMs2",'Resumo-DB'!$N$4,"requisição","DELETE /pecas/:id") -> 22.6 | BO7: =BB7-BL7-BI7 -> 3.9055556 | BP7: =BC7-BM7-BJ7 -> 0.985 | BQ7: =BD7-BN7-BK7 -> 11.2 | BR7: 33.92 | BS7: 6.77 | BT7: 6.3
B8: GET /aeronaves | C8: 10 | D8: 0 | E8: 0 | F8: 17.9 | G8: 14 | H8: 26 | I8: 17.5 | J8: 25.3 | K8: 26 | L8: 26 | M8: =(F8-P8)/2 -> 0.7405 | N8: =(G8-Q8)/2 -> 0.155 | O8: =(H8-R8)/2 -> 0.715 | P8: =GETPIVOTDATA("Média de Duração (ms)",'Resumo-DB'!$B$4,"requisição","GET /aeronaves/") -> 16.419 | Q8: =GETPIVOTDATA("Mín. de Duração (ms)",'Resumo-DB'!$B$4,"requisição","GET /aeronaves/") -> 13.69 | R8: =GETPIVOTDATA("Máx. de Duração (ms)",'Resumo-DB'!$B$4,"requisição","GET /aeronaves/") -> 24.57 | S8: =F8-P8-M8 -> 0.7405 | T8: =G8-Q8-N8 -> 0.155 | U8: =H8-R8-O8 -> 0.715 | V8: 12.22 | W8: 173.8 | X8: 1.97 | Z8: GET /aeronaves | AA8: 50 | AB8: 0 | AC8: 0 | AD8: 36.36 | AE8: 17 | AF8: 71 | AG8: 34.5 | AH8: 52 | AI8: 58.8 | AJ8: 71 | AK8: =(AD8-AN8)/2 -> 3.6756122 | AL8: =(AE8-AO8)/2 -> 1.35 | AM8: =(AF8-AP8)/2 -> 1.1 | AN8: =GETPIVOTDATA("Média de Duração (ms)",'Resumo-DB'!$H$4,"requisição","GET /aeronaves/") -> 29.008776 | AO8: =GETPIVOTDATA("Mín. de Duração (ms)",'Resumo-DB'!$H$4,"requisição","GET /aeronaves/") -> 14.3 | AP8: =GETPIVOTDATA("Máx. de Duração (ms)",'Resumo-DB'!$H$4,"requisição","GET /aeronaves/") -> 68.8 | AQ8: =AD8-AN8-AK8 -> 3.6756122 | AR8: =AE8-AO8-AL8 -> 1.35 | AS8: =AF8-AP8-AM8 -> 1.1 | AT8: 18.96 | AU8: 274.5 | AV8: 3.06 | AX8: GET /aeronaves | AY8: 100 | AZ8: 0 | BA8: 0 | BB8: 31.86 | BC8: 11 | BD8: 66 | BE8: 31 | BF8: 48 | BG8: 54.95 | BH8: 65.95 | BI8: =(BB8-BL8)/2 -> 3.9180612 | BJ8: =(BC8-BM8)/2 -> 1.21 | BK8: =(BD8-BN8)/2 -> 8.025 | BL8: =GETPIVOTDATA("Média de duracaoMs2",'Resumo-DB'!$N$4,"requisição","GET /aeronaves/") -> 24.023878 | BM8: =GETPIVOTDATA("Mín. de duracaoMs2",'Resumo-DB'!$N$4,"requisição","GET /aeronaves/") -> 8.58 | BN8: =GETPIVOTDATA("Máx. de duracaoMs2",'Resumo-DB'!$N$4,"requisição","GET /aeronaves/") -> 49.95 | BO8: =BB8-BL8-BI8 -> 3.9180612 | BP8: =BC8-BM8-BJ8 -> 1.21 | BQ8: =BD8-BN8-BK8 -> 8.025 | BR8: 33.81 | BS8: 496.86 | BT8: 5.45
B9: GET /etapas | C9: 10 | D9: 0 | E9: 0 | F9: 8.5 | G9: 7 | H9: 11 | I9: 8 | J9: 10.9 | K9: 11 | L9: 11 | M9: =(F9-P9)/2 -> 0.824 | N9: =(G9-Q9)/2 -> 0.845 | O9: =(H9-R9)/2 -> 0.41 | P9: =GETPIVOTDATA("Média de Duração (ms)",'Resumo-DB'!$B$4,"requisição","GET /etapas/") -> 6.852 | Q9: =GETPIVOTDATA("Mín. de Duração (ms)",'Resumo-DB'!$B$4,"requisição","GET /etapas/") -> 5.31 | R9: =GETPIVOTDATA("Máx. de Duração (ms)",'Resumo-DB'!$B$4,"requisição","GET /etapas/") -> 10.18 | S9: =F9-P9-M9 -> 0.824 | T9: =G9-Q9-N9 -> 0.845 | U9: =H9-R9-O9 -> 0.41 | V9: 12.35 | W9: 43.79 | X9: 1.95 | Z9: GET /etapas | AA9: 50 | AB9: 0 | AC9: 0 | AD9: 20.5 | AE9: 8 | AF9: 42 | AG9: 20 | AH9: 30.9 | AI9: 41 | AJ9: 42 | AK9: =(AD9-AN9)/2 -> 4.2052 | AL9: =(AE9-AO9)/2 -> 1.34 | AM9: =(AF9-AP9)/2 -> 7.1 | AN9: =GETPIVOTDATA("Média de Duração (ms)",'Resumo-DB'!$H$4,"requisição","GET /etapas/") -> 12.0896 | AO9: =GETPIVOTDATA("Mín. de Duração (ms)",'Resumo-DB'!$H$4,"requisição","GET /etapas/") -> 5.32 | AP9: =GETPIVOTDATA("Máx. de Duração (ms)",'Resumo-DB'!$H$4,"requisição","GET /etapas/") -> 27.8 | AQ9: =AD9-AN9-AK9 -> 4.2052 | AR9: =AE9-AO9-AL9 -> 1.34 | AS9: =AF9-AP9-AM9 -> 7.1 | AT9: 19.16 | AU9: 67.95 | AV9: 3.03 | AX9: GET /etapas | AY9: 100 | AZ9: 0 | BA9: 0 | BB9: 20.11 | BC9: 5 | BD9: 42 | BE9: 20 | BF9: 30.8 | BG9: 34 | BH9: 41.99 | BI9: =(BB9-BL9)/2 -> 4.7084 | BJ9: =(BC9-BM9)/2 -> 0.73 | BK9: =(BD9-BN9)/2 -> 9.02 | BL9: =GETPIVOTDATA("Média de duracaoMs2",'Resumo-DB'!$N$4,"requisição","GET /etapas/") -> 10.6932 | BM9: =GETPIVOTDATA("Mín. de duracaoMs2",'Resumo-DB'!$N$4,"requisição","GET /etapas/") -> 3.54 | BN9: =GETPIVOTDATA("Máx. de duracaoMs2",'Resumo-DB'!$N$4,"requisição","GET /etapas/") -> 23.96 | BO9: =BB9-BL9-BI9 -> 4.7084 | BP9: =BC9-BM9-BJ9 -> 0.73 | BQ9: =BD9-BN9-BK9 -> 9.02 | BR9: 33.97 | BS9: 120.48 | BT9: 5.37
